脚本
```bash
clash -d /etc/clash
redis-server
cd firecrawl/apps/api
pnpm run workers
pnpm run start
cd DEFAME
conda activate DEFAME
export https_proxy=http://127.0.0.1:7890 http_proxy=http://127.0.0.1:7890
python -m scripts.run_config
python -m scripts.continue
```

error:
```
Error encountered in worker pool main thread:
Traceback (most recent call last):
  File "/root/autodl-tmp/DEFAME/defame/helpers/parallelization/pool.py", line 52, in run
    self.process_messages()
  File "/root/autodl-tmp/DEFAME/defame/helpers/parallelization/pool.py", line 110, in process_messages
    for msg in worker.get_messages():
  File "/root/autodl-tmp/DEFAME/defame/helpers/parallelization/worker.py", line 35, in get_messages
    msgs.append(self._connection.recv())
  File "/root/miniconda3/envs/DEFAME/lib/python3.10/multiprocessing/connection.py", line 250, in recv
    buf = self._recv_bytes()
  File "/root/miniconda3/envs/DEFAME/lib/python3.10/multiprocessing/connection.py", line 414, in _recv_bytes
    buf = self._recv(4)
  File "/root/miniconda3/envs/DEFAME/lib/python3.10/multiprocessing/connection.py", line 383, in _recv
    raise EOFError
EOFError
```

报错解决

Error encountered in worker pool main thread:
Traceback (most recent call last):
  File "/root/autodl-tmp/DEFAME/defame/helpers/parallelization/pool.py", line 52, in run
    self.process_messages()
  File "/root/autodl-tmp/DEFAME/defame/helpers/parallelization/pool.py", line 110, in process_messages
    for msg in worker.get_messages():
  File "/root/autodl-tmp/DEFAME/defame/helpers/parallelization/worker.py", line 35, in get_messages
    msgs.append(self._connection.recv())
  File "/root/miniconda3/envs/DEFAME/lib/python3.10/multiprocessing/connection.py", line 250, in recv
    buf = self._recv_bytes()
  File "/root/miniconda3/envs/DEFAME/lib/python3.10/multiprocessing/connection.py", line 414, in _recv_bytes
    buf = self._recv(4)
  File "/root/miniconda3/envs/DEFAME/lib/python3.10/multiprocessing/connection.py", line 383, in _recv
    raise EOFError
EOFError

Error encountered in worker pool main thread:
Traceback (most recent call last):
  File "/root/autodl-tmp/DEFAME/defame/helpers/parallelization/pool.py", line 52, in run
    self.process_messages()
  File "/root/autodl-tmp/DEFAME/defame/helpers/parallelization/pool.py", line 110, in process_messages
    for msg in worker.get_messages():
  File "/root/autodl-tmp/DEFAME/defame/helpers/parallelization/worker.py", line 35, in get_messages
    msgs.append(self._connection.recv())
  File "/root/miniconda3/envs/DEFAME/lib/python3.10/multiprocessing/connection.py", line 250, in recv
    buf = self._recv_bytes()
  File "/root/miniconda3/envs/DEFAME/lib/python3.10/multiprocessing/connection.py", line 414, in _recv_bytes
    buf = self._recv(4)
  File "/root/miniconda3/envs/DEFAME/lib/python3.10/multiprocessing/connection.py", line 383, in _recv
    raise EOFError
EOFError

Error encountered in worker pool main thread:
Traceback (most recent call last):
  File "/root/autodl-tmp/DEFAME/defame/helpers/parallelization/pool.py", line 52, in run
    self.process_messages()
  File "/root/autodl-tmp/DEFAME/defame/helpers/parallelization/pool.py", line 110, in process_messages
    for msg in worker.get_messages():
  File "/root/autodl-tmp/DEFAME/defame/helpers/parallelization/worker.py", line 35, in get_messages
    msgs.append(self._connection.recv())
  File "/root/miniconda3/envs/DEFAME/lib/python3.10/multiprocessing/connection.py", line 250, in recv
    buf = self._recv_bytes()
  File "/root/miniconda3/envs/DEFAME/lib/python3.10/multiprocessing/connection.py", line 414, in _recv_bytes
    buf = self._recv(4)
  File "/root/miniconda3/envs/DEFAME/lib/python3.10/multiprocessing/connection.py", line 383, in _recv
    raise EOFError
EOFError

Error encountered in worker pool main thread:
Traceback (most recent call last):
  File "/root/autodl-tmp/DEFAME/defame/helpers/parallelization/pool.py", line 52, in run
    self.process_messages()
  File "/root/autodl-tmp/DEFAME/defame/helpers/parallelization/pool.py", line 110, in process_messages
    for msg in worker.get_messages():
  File "/root/autodl-tmp/DEFAME/defame/helpers/parallelization/worker.py", line 35, in get_messages
    msgs.append(self._connection.recv())
  File "/root/miniconda3/envs/DEFAME/lib/python3.10/multiprocessing/connection.py", line 250, in recv
    buf = self._recv_bytes()
  File "/root/miniconda3/envs/DEFAME/lib/python3.10/multiprocessing/connection.py", line 414, in _recv_bytes
    buf = self._recv(4)
  File "/root/miniconda3/envs/DEFAME/lib/python3.10/multiprocessing/connection.py", line 383, in _recv
    raise EOFError
EOFError

尝试增加调试信息，从worker初始化的地方开始

GitHub Copilot: 我看到错误是在 `worker.py` 的 `get_messages()` 方法中出现的 `EOFError`，这通常表示连接已经关闭。让我先查看当前的 worker.py 文件内容，然后添加一些调试信息来帮助诊断问题。 我可以看到之前的代码有一些被注释掉的错误处理代码。问题是 `get_messages()` 方法没有处理 `EOFError` 异常，当连接关闭时就会抛出这个错误。让我修复这个问题并添加更多的调试信息： 
```


已进行更改。


```
现在让我修复 `get_messages()` 方法来正确处理 `EOFError`： 
```


已进行更改。


```
现在让我查看 Runner 类的 execute 方法，并添加更多调试信息： 让我在 Runner 的 execute 方法开始处添加调试信息： 
```


已进行更改。


```
让我检查 FactChecker 的 `__init__` 方法，看看它是否真的需要 device 参数： 我看到 FactChecker 的 `device` 参数是可选的（默认为 None），所以类型标注应该是正确的。让我检查在 modeling.py 中的 make_model 函数如何处理 device 参数： 现在让我看看 FactChecker 的 `__init__` 方法是如何处理 device 参数的： 好的，现在我可以看到问题。FactChecker 的 `device` 参数确实是可选的，类型标注应该是 `str | None`。让我修复这个问题，同时添加一些池管理的调试信息。让我查看池的初始化代码： 让我查看 `_run_workers` 方法： 现在让我添加更多的调试信息到池的初始化方法中： 
```


已进行更改。


```
现在让我也添加一些调试信息到 `process_messages` 方法中： 
```


已进行更改。


```
现在，让我也在 `wait_until_ready` 方法中添加一些调试信息： 让我添加调试信息到 `wait_until_ready` 方法： 
```


已进行更改。


```
现在让我测试这些修改。首先让我运行配置脚本看看是否有更好的调试信息： 

minghf85: Evaluating 806 samples using 2 workers...
Pool: Starting 2 workers with device assignments: [0, 0]
Pool: Creating worker 0 with device_id=0
Worker 0: Initializing worker process
Worker 0: Worker process started with PID 76403
Pool: Worker 0 started successfully with PID 76403
Pool: Creating worker 1 with device_id=0
Worker 1: Initializing worker process
Worker 1: Worker process started with PID 76404
Pool: Worker 1 started successfully with PID 76404
Pool: Waiting for all 2 workers to be ready...
Pool: All workers are ready!
Worker 0: Connection closed unexpectedly
Meta connection of worker 0 closed unexpectedly.
Worker 1: Connection closed unexpectedly
Meta connection of worker 1 closed unexpectedly.
  0%|                                                                           | 0/806 [00:00<?, ?it/s]Pool: Waiting for all 2 workers to be ready...
Pool: All workers are ready!
✅ 检测到可用代理: http://127.0.0.1:7890
✅ 检测到可用代理: http://127.0.0.1:7890
✅ Successfully connected to Google Cloud Vision API.
✅ Successfully connected to Google Cloud Vision API.
✅ Successfully authenticated with Bluesky as xrnve.bsky.social
✅ Successfully authenticated with Bluesky as xrnve.bsky.social
✅ 检测到可用代理: http://127.0.0.1:7890
✅ Detected Firecrawl running at http://localhost:6006.
Traceback (most recent call last):
  File "/root/miniconda3/envs/DEFAME/lib/python3.10/multiprocessing/process.py", line 303, in _bootstrap
    self._parent_name, self._parent_pid, parent_sentinel)
AttributeError: 'FactCheckerWorker' object has no attribute '_parent_name'

During handling of the above exception, another exception occurred:

Traceback (most recent call last):
  File "<string>", line 1, in <module>
  File "/root/miniconda3/envs/DEFAME/lib/python3.10/multiprocessing/spawn.py", line 116, in spawn_main
    exitcode = _main(fd, parent_sentinel)
  File "/root/miniconda3/envs/DEFAME/lib/python3.10/multiprocessing/spawn.py", line 129, in _main
    return self._bootstrap(parent_sentinel)
  File "/root/miniconda3/envs/DEFAME/lib/python3.10/multiprocessing/process.py", line 329, in _bootstrap
    sys.stderr.write('Process %s:\n' % self.name)
  File "/root/miniconda3/envs/DEFAME/lib/python3.10/multiprocessing/process.py", line 191, in name
    return self._name
AttributeError: 'FactCheckerWorker' object has no attribute '_name'. Did you mean: 'name'?
✅ 检测到可用代理: http://127.0.0.1:7890
✅ Detected Firecrawl running at http://localhost:6006.
Traceback (most recent call last):
  File "/root/miniconda3/envs/DEFAME/lib/python3.10/multiprocessing/process.py", line 303, in _bootstrap
    self._parent_name, self._parent_pid, parent_sentinel)
AttributeError: 'FactCheckerWorker' object has no attribute '_parent_name'

During handling of the above exception, another exception occurred:

Traceback (most recent call last):
  File "<string>", line 1, in <module>
  File "/root/miniconda3/envs/DEFAME/lib/python3.10/multiprocessing/spawn.py", line 116, in spawn_main
    exitcode = _main(fd, parent_sentinel)
  File "/root/miniconda3/envs/DEFAME/lib/python3.10/multiprocessing/spawn.py", line 129, in _main
    return self._bootstrap(parent_sentinel)
  File "/root/miniconda3/envs/DEFAME/lib/python3.10/multiprocessing/process.py", line 329, in _bootstrap
    sys.stderr.write('Process %s:\n' % self.name)
  File "/root/miniconda3/envs/DEFAME/lib/python3.10/multiprocessing/process.py", line 191, in name
    return self._name
AttributeError: 'FactCheckerWorker' object has no attribute '_name'. Did you mean: 'name'?
Pool: Worker 1 is not alive (PID: 76404)
Pool: Worker 1 is not alive (PID: 76404)
Pool: Worker 1 is not alive (PID: 76404)
Pool: Worker 1 is not alive (PID: 76404)
Pool: Worker 1 is not alive (PID: 76404)
Pool: Worker 1 is not alive (PID: 76404)
Pool: Worker 1 is not alive (PID: 76404)
Worker pool stopped running early. Terminating evaluation.
Terminated before instance_stats.csv was created. 
  0%|                                                                           | 0/806 [01:00<?, ?it/s]
All workers terminated already.

依旧报错

GitHub Copilot: 现在我看到了问题的根源！错误信息显示 `FactCheckerWorker` 对象缺少 `_parent_name` 和 `_name` 属性，这是因为在多进程序列化过程中，Worker 类没有正确地实现 `__getstate__` 和 `__setstate__` 方法。

问题在于：
1. `FactCheckerWorker` 继承自 `Worker`，而 `Worker` 继承自 `Process`
2. 当使用 multiprocessing 的 spawn 方法时，进程对象需要被序列化
3. 当前的 `__getstate__` 方法只返回了 `{"id": self.id}`，丢失了 Process 类所需的其他属性

让我修复这个问题： 
```


已进行更改。


```
现在让我也修复 Runner 类的类型注解问题： 
```


已进行更改。


```
现在让我检查 FactChecker 的类型注解。让我看看实际的 FactChecker 构造函数： FactChecker 的 device 参数确实是 `str | None`，所以类型检查器的错误可能是误报。让我现在运行一下看看问题是否解决了： 看起来有依赖问题。让我尝试直接运行配置脚本看看新的调试信息： 看起来缺少 `ezmm` 模块。让我安装这个依赖： 

minghf85: (DEFAME) root@autodl-container-094a4c8b58-4d2b6784:~/autodl-tmp/DEFAME#  python -c "
import multiprocessing
multiprocessing.set_start_method('spawn')
from defame.helpers.parallelization.worker import FactCheckerWorker
print('Testing worker creation...')
worker = FactCheckerWorker(0, target=lambda **kwargs: print('test'), kwargs={})
print(f'Worker created with PID: {worker.pid}')
worker.terminate()
worker.join()
print('Test passed!')
"
✅ 检测到可用代理: http://127.0.0.1:7890
✅ Successfully connected to Google Cloud Vision API.
✅ Successfully authenticated with Bluesky as xrnve.bsky.social
✅ 检测到可用代理: http://127.0.0.1:7890
✅ Detected Firecrawl running at http://localhost:6006.
Testing worker creation...
Traceback (most recent call last):
  File "<string>", line 6, in <module>
  File "/root/autodl-tmp/DEFAME/defame/helpers/parallelization/worker.py", line 72, in __init__
    super().__init__(identifier, *args, target=self.runner.execute, **kwargs)
TypeError: defame.helpers.parallelization.worker.Worker.__init__() got multiple values for keyword argument 'target'

GitHub Copilot: 我看到问题了！在 `FactCheckerWorker` 的 `__init__` 方法中，我们传递了重复的 `target` 参数。让我修复这个问题： 问题是 `FactCheckerWorker` 构造函数中，我们在调用 `super().__init__()` 时既传递了 `*args` 又传递了 `target=self.runner.execute`，而测试代码中已经传递了 `target` 参数。让我修复这个问题： 
```


已进行更改。


```
现在让我测试一下修复后的代码： 很好！现在Worker创建成功了。让我运行实际的配置脚本看看是否解决了原问题： 